Workbook

Sheet OBR
A3: Republic of the Philippines
A4: PROVINCE OF CAMARINES NORTE
A6: OBLIGATION REQUEST
A9: Payee | E9: ALMIRANTE A. ABAD & CO.
A11: Office | E11: Provincial Agriculturist Office
A13: Address | E13: DAET, CAMS. NORTE
A15: Responsibility | E15: Particulars | F15: F.P.P. | G15: New Account | K15: Amount
A16: Center | G16: Code
A19: 8711 | E19: SALARY FOR THE MONTH OF | F19: 8710-001-1 | G19: 5 | H19: 01 | I19: 01 | J19: 010 | K19: ='payroll(FEB)'!E46 -> 1538150 | L19: SALARY
E20: FEBRUARY 2026 | F20: 01-016-001 | G20: 5 | H20: 01 | I20: 03 | J20: 010 | K20: ='payroll(FEB)'!G46 -> 184578 | L20: GSIS
F21: 001-001 | G21: 5 | H21: 01 | I21: 03 | J21: 020 | K21: ='PAG-IBIG'!I70 -> 7200 | L21: PAGIBIG
G22: 5 | H22: 01 | I22: 03 | J22: 030 | K22: ='PHIC (1)'!X50 -> 37646.79 | L22: PHILHEALTH
G23: 5 | H23: 01 | I23: 03 | J23: 040 | K23: ='payroll(FEB)'!H46 -> 3600 | L23: EC
G24: 5 | H24: 01 | I24: 2 | J24: 010
G25: 5 | H25: 01 | I25: 02 | J25: 010 | K25: ='payroll(FEB)'!AC46 -> 72000 | L25: PERA
G26: 5 | H26: 01 | I26: 02 | J26: 020 | K26: ='payroll(FEB)'!AD46 -> 9500 | L26: RA
G27: 5 | H27: 01 | I27: 02 | J27: 030 | K27: ='payroll(FEB)'!AE46 -> 9500 | L27: TA
K31: =SUM(K19:K27) -> 1862174.8
A32: A. Certified | F32: B. Certified
D33: Charges to budget necessary,
D34: lawful and under my direct | F34: Existence of available appropriation
D35: supervision
D36: Supporting documents valid,
D37: proper and legal
A44: ALMIRANTE A. ABAD | F44: MERCEDES M. ALFUERTE
A45: PROVINCIAL AGRICULTURIST | F45: Provincial Budget Officer
C48: Date: ____________________ | F48: ____________________________
F49: Date

Sheet VOUCHER
A1: Republic of the Philippines
A2: PROVINCE OF CAMARINES NORTE
A5: DISBURSEMENT VOUCHER | M5: No.
A8: Mode of | E8: Check | J8: Cash | P8: Others
A9: Payment
H10: TIN/Employee No. | N10: Obligation Request No.
A11: Payee | C11: ALMIRANTE A. ABAD & CO.
G12: Responsibility Center
A13: Address | D13: Daet, Cams. Norte | H13: Office/Unit/Project | M13: Code
H14: OPAG | M14: 8711
A15: E X P L A N A T I O N | P15: AMOUNT
A18: TO PAYMENT for SALARIES, PERA/RATA for the month of FEBRUARY 2026 of the above personnel
B19: as per supporting papers hereto attached IN THE AMOUNT OF ….. | P19: ='payroll(FEB)'!AF46 -> 688361.67
S20: =415221-214589.56 -> 200631.44
T24: 156282.14
S30: 182986.22
S31: -181599.06
Q32: =P32-#REF! -> #REF! | R32: 213692.7 | S32: =SUM(S30:S31) -> 1387.16
R33: =P32-R32 -> -213692.7
P34: ='payroll(FEB)'!AF46 -> 688361.67
A35: A. Certified | H35: B. Certified | P35: P | S35: =212306.07-212206.22 -> 99.85
C36: Allotment obligated for the purpose as | H36: Funds Available
A37: indicated above
C38: Supporting documents complete
A41: IMELDA M. FLORES | H41: DANTE E. MANLAPAZ
A42: Provincial Accountant | H42: Provincial Treasurer
A44: Date | H44: Date
A45: C. Approved for Payment | H45: D. Received Payment
G46: Check No. | K46: Bank Name | N46: Date
G48: Signature
A51: JOSEPH V. ASCUTIA | G51: Printed Name | N51: Date
A52: Acting Governor
G53: OR/Other Documents | M53: JEV | P53: Date
M54: No.
A64: Republic of the Philippines
A65: PROVINCE OF CAMARINES NORTE
A68: DISBURSEMENT VOUCHER | M68: No.
A71: Mode of | E71: Check | J71: Cash | P71: Others
A72: Payment
H73: TIN/Employee No. | M73: Obligation Request No.
...

Sheet payroll(FEB)
Q1: PROVINCIAL PAYROLL
N2: We hereby acknowledge to have received from _________________, ICO of Camarines Norte, the sums herein specified opposite our respective names, the same being full compensation for our services rendered during the period stated below, to the correctness of which we hereby severally certify.
A3: Number | C3: SALARY | F3: D E D U C T I O N S | AG3: Number
D4: DESIGNATION | F4: G S I S | Q4: PAG-IBIG | V4: Philhealth | AB4: C N G W M P C | AF4: Amount
AA5: *POLICY
C6: NAME | F6: Life & Retirement | AA6: PNB | AF6: Paid in Cash
E7: SALARY | F7: Personal | G7: Govt | H7: EC | I7: Real Estate | J7: Conso | K7: Emergency | L7: GSIS | M7: GSIS | O7: COMPUTER | P7: Reg | Q7: Personal | R7: Gov't | S7: Multi-Purpose | T7: Calamity | U7: Overpayment | V7: Personal | W7: Gov't | X7: Withholding | Y7: DBP | Z7: LBP | AA7: DBP | AB7: CNGWMPC | AC7: PERA | AE7: TA | AF7: (Cr. A-1)
B8: EMPLOYEE | C8: FEBRUARY 1-28, 2026 | F8: Share | G8: Share | I8: Loan | J8: Loan | K8: Loan | L8: MPL | M8: MPL LITE | N8: GFAL | O8: LOAN | P8: Policy | Q8: Share | R8: Share | S8: Loan | T8: Loan | U8: for Sept 2025 | V8: Share | W8: Share | X8: Tax | Y8: Loan | Z8: Loan | AA8: Loan | AC8: 46054 | AD8: RA
B9: CODE | C9: 2 | D9: 3 | E9: 4 | F9: 6 | G9: 7 | H9: 8 | I9: 9 | J9: 10 | K9: 12 | L9: 13 | N9: 14 | P9: 15 | Q9: 16 | R9: 17 | S9: 18 | T9: 19 | U9: 20 | V9: 21 | W9: 22 | X9: 23 | Y9: 24 | Z9: 25 | AA9: 11 | AB9: 28 | AC9: 40 | AD9: 41 | AE9: 42 | AF9: 43
A10: 1 | B10: 8711.0-001 | C10: ALMIRANTE A. ABAD | D10: PA | E10: =' gsis'!H16 -> 132280 | F10: =' gsis'!I16 -> 11905.2 | G10: =' gsis'!J16 -> 15873.6 | H10: =' gsis'!K16 -> 100 | Q10: ='PAG-IBIG'!H14 -> 2000 | R10: ='PAG-IBIG'!I14 -> 200 | V10: ='PHIC (1)'!W14 -> 2500 | W10: ='PHIC (1)'!X14 -> 2500 | X10: =WTAX!H14 -> 26527.12 | AB10: =CNGWMPC!S15 -> 26407.68 | AC10: 2000 | AD10: 9500 | AE10: 9500 | AF10: =E10-F10-I10-J10-K10-L10-M10-N10-O10-P10-Q10-S10-T10-V10-X10-Y10-Z10-AB10+AC10+AD10+AE10 -> 83940 | AG10: 1
A11: 2 | B11: 8711.0-002 | C11: RAPHY B. BELARDO | D11: POIV | E11: =' gsis'!H17 -> 81564 | F11: =' gsis'!I17 -> 7340.76 | G11: =' gsis'!J17 -> 9787.68 | H11: =' gsis'!K17 -> 100 | L11: =' gsis'!R17 -> 12189.13 | M11: =' gsis'!S17 -> 2333.33 | N11: =' gsis'!Q17 -> 9634.44 | Q11: ='PAG-IBIG'!H15 -> 500 | R11: ='PAG-IBIG'!I15 -> 200 | V11: ='PHIC (1)'!W15 -> 2039.1 | W11: ='PHIC (1)'!X15 -> 2039.1 | X11: =WTAX!H15 -> 12862.52 | Y11: =DBP!G19 -> 14483.61 | AB11: =CNGWMPC!S16 -> 701.11 | AC11: 2000 | AF11: =E11-F11-I11-J11-K11-L11-M11-N11-O11-P11-Q11-S11-T11-V11-X11-Y11-Z11-AB11+AC11+AD11+AE11 -> 21480 | AG11: 2
A12: 3 | B12: 8711.0-004 | C12: MARIA GISELA C. NASOL | D12: SAO | E12: =' gsis'!H18 -> 78162 | F12: =' gsis'!I18 -> 7034.58 | G12: =' gsis'!J18 -> 9379.44 | H12: =' gsis'!K18 -> 100 | K12: =' gsis'!N18 -> 0 | L12: =' gsis'!R18 -> 12177.29 | M12: =' gsis'!S18 -> 2333.33 | N12: =' gsis'!Q18 -> 9634.44 | O12: =' gsis'!P18 -> 1966.67 | Q12: ='PAG-IBIG'!H16 -> 700 | R12: ='PAG-IBIG'!I16 -> 200 | S12: ='PAG-IBIG'!J16 -> 1500 | V12: ='PHIC (1)'!W16 -> 1954.05 | W12: ='PHIC (1)'!X16 -> 1954.05 | X12: =WTAX!H16 -> 11950.31 | Y12: =DBP!G17 -> 2633.38 | Z12: =LBP!H20 -> 15756.7 | AB12: =CNGWMPC!S17 -> 3131.25 | AC12: 2000 | AF12: =E12-F12-I12-J12-K12-L12-M12-N12-O12-P12-Q12-S12-T12-V12-X12-Y12-Z12-AB12+AC12+AD12+AE12 -> 9390 | AG12: 3
A13: 4 | B13: 8711.0-005 | C13: MARLENE V. CERENO | D13: POII | E13: =' gsis'!H19 -> 41413 | F13: =' gsis'!I19 -> 3727.17 | G13: =' gsis'!J19 -> 4969.56 | H13: =' gsis'!K19 -> 100 | K13: =' gsis'!N19 -> 655.56 | L13: =' gsis'!R19 -> 4408.9 | M13: =' gsis'!S19 -> 2333.33 | O13: =' gsis'!P19 -> 1966.67 | P13: =' gsis'!M19 -> 300 | Q13: ='PAG-IBIG'!H17 -> 200 | R13: ='PAG-IBIG'!I17 -> 200 | V13: ='PHIC (1)'!W17 -> 1035.32 | W13: ='PHIC (1)'!X17 -> 1035.33 | X13: =WTAX!H17 -> 3394.69 | AB13: =CNGWMPC!S18 -> 1301.36 | AC13: 2000 | AF13: =E13-F13-I13-J13-K13-L13-M13-N13-O13-P13-Q13-S13-T13-V13-X13-Y13-Z13-AB13+AC13+AD13+AE13 -> 24090 | AG13: 4
A14: 5 | B14: 8711.0-007 | C14: MELINDA R. BARCELONA | D14: AO V | E14: =' gsis'!H20 -> 51304 | F14: =' gsis'!I20 -> 4617.36 | G14: =' gsis'!J20 -> 6156.48 | H14: =' gsis'!K20 -> 100 | K14: =' gsis'!N20 -> 0 | L14: =' gsis'!R20 -> 7992.93 | M14: =' gsis'!S20 -> 2333.33 | N14: =' gsis'!Q20 -> 9634.44 | O14: =' gsis'!P20 -> 1966.67 | P14: =' gsis'!M20 -> 200 | Q14: ='PAG-IBIG'!H18 -> 400 | R14: ='PAG-IBIG'!I18 -> 200 | T14: ='PAG-IBIG'!K18 -> 0 | V14: ='PHIC (1)'!W18 -> 1282.6 | W14: ='PHIC (1)'!X18 -> 1282.6 | X14: =WTAX!H18 -> 5518.71 | Y14: =DBP!G18 -> 5266.77 | AB14: =CNGWMPC!S19 -> 2971.19 | AC14: 2000 | AF14: =E14-F14-I14-J14-K14-L14-M14-N14-O14-P14-Q14-S14-T14-V14-X14-Y14-Z14-AB14+AC14+AD14+AE14 -> 11120 | AG14: 5
A15: 6 | B15: 8711.0-008 | C15: ELNORA B. OBUSAN | D15: COIV | E15: =' gsis'!H21 -> 38118 | F15: =' gsis'!I21 -> 3430.62 | G15: =' gsis'!J21 -> 4574.16 | H15: =' gsis'!K21 -> 100 | K15: =' gsis'!N21 -> 1311.12 | L15: =' gsis'!R21 -> 6298.92 | P15: =' gsis'!M21 -> 200 | Q15: ='PAG-IBIG'!H19 -> 500 | R15: ='PAG-IBIG'!I19 -> 200 | V15: ='PHIC (1)'!W19 -> 952.95 | W15: ='PHIC (1)'!X19 -> 952.95 | X15: =WTAX!H19 -> 2597.29 | Y15: =DBP!G16 -> 7900.15 | AB15: =CNGWMPC!S20 -> 6756.95 | AC15: 2000 | AF15: =E15-F15-I15-J15-K15-L15-M15-N15-O15-P15-Q15-S15-T15-V15-X15-Y15-Z15-AB15+AC15+AD15+AE15 -> 10170 | AG15: 6
A16: 7 | B16: 8711.0-009 | C16: EDWIN V. DE JESUS | D16: AQII | E16: =' gsis'!H22 -> 41006 | F16: =' gsis'!I22 -> 3690.54 | G16: =' gsis'!J22 -> 4920.72 | H16: =' gsis'!K22 -> 100 | K16: =' gsis'!N22 -> 0 | L16: =' gsis'!R22 -> 6109.05 | M16: =' gsis'!S22 -> 1866.67 | O16: =' gsis'!P22 -> 1966.67 | Q16: ='PAG-IBIG'!H20 -> 200 | R16: ='PAG-IBIG'!I20 -> 200 | V16: ='PHIC (1)'!W20 -> 1025.15 | W16: ='PHIC (1)'!X20 -> 1025.15 | X16: =WTAX!H20 -> 3307.28 | Z16: =LBP!H17 -> 16413.23 | AB16: =CNGWMPC!S21 -> 707.41 | AC16: 2000 | AF16: =E16-F16-I16-J16-K16-L16-M16-N16-O16-P16-Q16-S16-T16-V16-X16-Y16-Z16-AB16+AC16+AD16+AE16 -> 7720 | AG16: 7
A17: 8 | B17: 8711.0-010 | C17: GLENDA M. MAGANA | D17: AA IV | E17: =' gsis'!H23 -> 17209 | F17: =' gsis'!I23 -> 1548.81 | G17: =' gsis'!J23 -> 2065.08 | H17: =' gsis'!K23 -> 100 | K17: =' gsis'!N23 -> 0 | L17: =' gsis'!R23 -> 2236.76 | N17: =' gsis'!Q23 -> 5603.77 | O17: =' gsis'!P23 -> 1966.67 | Q17: ='PAG-IBIG'!H21 -> 400 | R17: ='PAG-IBIG'!I21 -> 200 | V17: ='PHIC (1)'!W21 -> 430.22 | W17: ='PHIC (1)'!X21 -> 430.23 | AB17: =CNGWMPC!S22 -> 702.77 | AC17: 2000 | AF17: =E17-F17-I17-J17-K17-L17-M17-N17-O17-P17-Q17-S17-T17-V17-X17-Y17-Z17-AB17+AC17+AD17+AE17 -> 6320 | AG17: 8
A18: 9 | B18: 8711.0-011 | C18: PEDRO S. VELACRUZ III | D18: PS | E18: =' gsis'!H24 -> 18133 | F18: =' gsis'!I24 -> 1631.97 | G18: =' gsis'!J24 -> 2175.96 | H18: =' gsis'!K24 -> 100 | L18: =' gsis'!R24 -> 2848.19 | Q18: ='PAG-IBIG'!H22 -> 200 | R18: ='PAG-IBIG'!I22 -> 200 | V18: ='PHIC (1)'!W22 -> 453.32 | W18: ='PHIC (1)'!X22 -> 453.33 | AB18: =CNGWMPC!S23 -> 6153.52 | AC18: 2000 | AF18: =E18-F18-I18-J18-K18-L18-M18-N18-O18-P18-Q18-S18-T18-V18-X18-Y18-Z18-AB18+AC18+AD18+AE18 -> 8846 | AG18: 9
A19: 10 | B19: 8711.0-012 | C19: SALLY R. ARCIGA | D19: AA III | E19: =' gsis'!H25 -> 16088 | F19: =' gsis'!I25 -> 1447.92 | G19: =' gsis'!J25 -> 1930.56 | H19: =' gsis'!K25 -> 100 | K19: =' gsis'!N25 -> 655.56 | L19: =' gsis'!R25 -> 2074.66 | O19: =' gsis'!P25 -> 1966.67 | P19: =' gsis'!M25 -> 100 | Q19: ='PAG-IBIG'!H23 -> 200 | R19: ='PAG-IBIG'!I23 -> 200 | S19: ='PAG-IBIG'!J23 -> 0 | T19: ='PAG-IBIG'!K23 -> 0 | V19: ='PHIC (1)'!W23 -> 402.2 | W19: ='PHIC (1)'!X23 -> 402.2 | Y19: =DBP!G21 -> 5266.77 | AB19: =CNGWMPC!S24 -> 804.22 | AC19: 2000 | AF19: =E19-F19-I19-J19-K19-L19-M19-N19-O19-P19-Q19-S19-T19-V19-X19-Y19-Z19-AB19+AC19+AD19+AE19 -> 5170 | AG19: 10
A20: 11 | B20: 8711.0-013 | C20: MACK LENNON G. QUIBRAL | D20: AT | E20: =' gsis'!H26 -> 25996 | F20: =' gsis'!I26 -> 2339.64 | G20: =' gsis'!J26 -> 3119.52 | H20: =' gsis'!K26 -> 100 | L20: =' gsis'!R26 -> 3467.78 | M20: =' gsis'!S26 -> 1816.67 | P20: =' gsis'!M26 -> 200 | Q20: ='PAG-IBIG'!H24 -> 200 | R20: ='PAG-IBIG'!I24 -> 200 | V20: ='PHIC (1)'!W24 -> 649.9 | W20: ='PHIC (1)'!X24 -> 649.9 | X20: =WTAX!H21 -> 537 | Y20: =DBP!G23 -> 4356.07 | Z20: =LBP!H18 -> 3788.1 | AB20: =CNGWMPC!S25 -> 800.84 | AC20: 2000 | AF20: =E20-F20-I20-J20-K20-L20-M20-N20-O20-P20-Q20-S20-T20-V20-X20-Y20-Z20-AB20+AC20+AD20+AE20 -> 9840 | AG20: 11
A21: 12 | B21: 8711.0-051 | C21: GEMMA S. JAUCIAN | D21: BIII | E21: =' gsis'!H27 -> 20408 | F21: =' gsis'!I27 -> 1836.72 | G21: =' gsis'!J27 -> 2448.96 | H21: =' gsis'!K27 -> 100 | K21: =' gsis'!N27 -> 655.56 | L21: =' gsis'!R27 -> 2631.62 | O21: =' gsis'!P27 -> 1966.67 | P21: =' gsis'!M27 -> 200 | Q21: ='PAG-IBIG'!H25 -> 200 | R21: ='PAG-IBIG'!I25 -> 200 | S21: ='PAG-IBIG'!J25 -> 0 | T21: ='PAG-IBIG'!K25 -> 970.5 | V21: ='PHIC (1)'!W25 -> 510.2 | W21: ='PHIC (1)'!X25 -> 510.2 | Y21: =DBP!G22 -> 6583.46 | AB21: =CNGWMPC!S26 -> 1383.27 | AC21: 2000 | AF21: =E21-F21-I21-J21-K21-L21-M21-N21-O21-P21-Q21-S21-T21-V21-X21-Y21-Z21-AB21+AC21+AD21+AE21 -> 5470 | AG21: 12
A22: 13 | B22: 8711.0-024 | C22: DULCE D. DORIMAN | D22: SR AG | E22: =' gsis'!H28 -> 52367 | F22: =' gsis'!I28 -> 4713.03 | G22: =' gsis'!J28 -> 6284.04 | H22: =' gsis'!K28 -> 100 | I22: =' gsis'!O28 -> 1533.5 | K22: =' gsis'!N28 -> 1138.73 | L22: =' gsis'!R28 -> 7801.77 | M22: =' gsis'!S28 -> 2333.33 | N22: =' gsis'!Q28 -> 9634.44 | Q22: ='PAG-IBIG'!H26 -> 200 | R22: ='PAG-IBIG'!I26 -> 200 | V22: ='PHIC (1)'!W26 -> 1309.17 | W22: ='PHIC (1)'!X26 -> 1309.18 | X22: =WTAX!H22 -> 5746.98 | Y22: =DBP!G25 -> 6263.95 | AB22: =CNGWMPC!S27 -> 902.1 | AC22: 2000 | AF22: =E22-F22-I22-J22-K22-L22-M22-N22-O22-P22-Q22-S22-T22-V22-X22-Y22-Z22-AB22+AC22+AD22+AE22-U22 -> 12790 | AG22: 13
A23: 14 | B23: 8711.0-016 | C23: SANTIAGO G. MALALUAN | D23: AGII | E23: =' gsis'!H29 -> 43090 | F23: =' gsis'!I29 -> 3878.1 | G23: =' gsis'!J29 -> 5170.8 | H23: =' gsis'!K29 -> 100 | K23: =' gsis'!N29 -> 0 | L23: =' gsis'!R29 -> 6433.73 | N23: =' gsis'!Q29 -> 9634.44 | P23: =' gsis'!M29 -> 500 | Q23: ='PAG-IBIG'!H27 -> 200 | R23: ='PAG-IBIG'!I27 -> 200 | V23: ='PHIC (1)'!W27 -> 1077.25 | W23: ='PHIC (1)'!X27 -> 1077.25 | X23: =WTAX!H23 -> 204.04 | AB23: =CNGWMPC!S28 -> 5692.44 | AC23: 2000 | AF23: =E23-F23-I23-J23-K23-L23-M23-N23-O23-P23-Q23-S23-T23-V23-X23-Y23-Z23-AB23+AC23+AD23+AE23 -> 17470 | AG23: 14
A24: 15 | B24: 8711.0-017 | C24: CELESTE M. SALVANERA | D24: SR AG | E24: =' gsis'!H30 -> 51304 | F24: =' gsis'!I30 -> 4617.36 | G24: =' gsis'!J30 -> 6156.48 | H24: =' gsis'!K30 -> 100 | N24: =' gsis'!Q30 -> 9634.44 | P24: =' gsis'!M30 -> 100 | Q24: ='PAG-IBIG'!H28 -> 200 | R24: ='PAG-IBIG'!I28 -> 200 | V24: ='PHIC (1)'!W28 -> 1282.6 | W24: ='PHIC (1)'!X28 -> 1282.6 | X24: =WTAX!H24 -> 5518.71 | AB24: =CNGWMPC!S29 -> 800.89 | AC24: 2000 | AF24: =E24-F24-I24-J24-K24-L24-M24-N24-O24-P24-Q24-S24-T24-V24-X24-Y24-Z24-AB24+AC24+AD24+AE24 -> 31150 | AG24: 15
A25: 16 | B25: 8711.0-021 | C25: ALGEM MARIE J. CLACIO | D25: AOIII | E25: =' gsis'!H31 -> 37024 | F25: =' gsis'!I31 -> 3332.16 | G25: =' gsis'!J31 -> 4442.88 | H25: =' gsis'!K31 -> 100 | O25: =' gsis'!P31 -> 1966.67 | Q25: ='PAG-IBIG'!H29 -> 200 | R25: ='PAG-IBIG'!I29 -> 200 | V25: ='PHIC (1)'!W29 -> 925.6 | W25: ='PHIC (1)'!X29 -> 925.6 | X25: =WTAX!H25 -> 2302.93 | AB25: =CNGWMPC!S30 -> 10646.64 | AC25: 2000 | AF25: =E25-F25-I25-J25-K25-L25-M25-N25-O25-P25-Q25-S25-T25-V25-X25-Y25-Z25-AB25+AC25+AD25+AE25 -> 19650 | AG25: 16
A26: 17 | B26: 8711.0-052 | C26: CHRISTINE L. PALAD | D26: AT | E26: =' gsis'!H32 -> 25996 | F26: =' gsis'!I32 -> 2339.64 | G26: =' gsis'!J32 -> 3119.52 | H26: =' gsis'!K32 -> 100 | Q26: ='PAG-IBIG'!H30 -> 200 | R26: ='PAG-IBIG'!I30 -> 200 | V26: ='PHIC (1)'!W30 -> 649.9 | W26: ='PHIC (1)'!X30 -> 649.9 | X26: =WTAX!H26 -> 537 | AB26: =CNGWMPC!S31 -> 1799.46 | AC26: 2000 | AF26: =E26-F26-I26-J26-K26-L26-M26-N26-O26-P26-Q26-S26-T26-V26-X26-Y26-Z26-AB26+AC26+AD26+AE26 -> 22470 | AG26: 17
A27: 18 | B27: 8711.0-026 | C27: CESAR R. MIRAÑA | D27: SR AG | E27: =' gsis'!H33 -> 52367 | F27: =' gsis'!I33 -> 4713.03 | G27: =' gsis'!J33 -> 6284.04 | H27: =' gsis'!K33 -> 100 | Q27: ='PAG-IBIG'!H50 -> 200 | R27: ='PAG-IBIG'!I50 -> 200 | V27: ='PHIC (1)'!W31 -> 1309.17 | W27: ='PHIC (1)'!X31 -> 1309.18 | AB27: =CNGWMPC!S32 -> 17734.8 | AC27: 2000 | AF27: =E27-F27-I27-J27-K27-L27-M27-N27-O27-P27-Q27-S27-T27-V27-X27-Y27-Z27-AB27+AC27+AD27+AE27 -> 30410 | AG27: 18
A28: 19 | B28: 8711.0-025 | C28: BRENDA R. MENESES | D28: AG II | E28: =' gsis'!H34 -> 41413 | F28: =' gsis'!I34 -> 3727.17 | G28: =' gsis'!J34 -> 4969.56 | H28: =' gsis'!K34 -> 100 | K28: =' gsis'!N34 -> 0 | L28: =' gsis'!R34 -> 4408.9 | M28: =' gsis'!S34 -> 2333.33 | N28: =' gsis'!Q34 -> 9634.44 | Q28: ='PAG-IBIG'!H51 -> 200 | R28: ='PAG-IBIG'!I51 -> 200 | V28: ='PHIC (1)'!W32 -> 1035.32 | W28: ='PHIC (1)'!X32 -> 1035.33 | X28: =WTAX!H27 -> 3394.69 | AB28: =CNGWMPC!S33 -> 8839.15 | AC28: 2000 | AF28: =E28-F28-I28-J28-K28-L28-M28-N28-O28-P28-Q28-S28-T28-V28-X28-Y28-Z28-AB28+AC28+AD28+AE28 -> 9840 | AG28: 19
A29: 20 | B29: 8711.0-027 | C29: RONNIE R. ASIS | D29: AG II | E29: =' gsis'!H35 -> 42241 | F29: =' gsis'!I35 -> 3801.69 | G29: =' gsis'!J35 -> 5068.92 | H29: =' gsis'!K35 -> 100 | L29: =' gsis'!R35 -> 7823.43 | N29: =' gsis'!Q35 -> 9634.44 | Q29: ='PAG-IBIG'!H52 -> 200 | R29: ='PAG-IBIG'!I52 -> 200 | V29: ='PHIC (1)'!W33 -> 1056.02 | W29: ='PHIC (1)'!X33 -> 1056.03 | X29: =WTAX!H28 -> 3572.44 | AB29: =CNGWMPC!S34 -> 702.98 | AC29: 2000 | AF29: =E29-F29-I29-J29-K29-L29-M29-N29-O29-P29-Q29-S29-T29-V29-X29-Y29-Z29-AB29+AC29+AD29+AE29 -> 17450 | AG29: 20
A30: 21 | B30: 8711.0-028 | C30: RYAN I. VILLAFLORES | D30: AGII | E30: =' gsis'!H36 -> 41006 | F30: =' gsis'!I36 -> 3690.54 | G30: =' gsis'!J36 -> 4920.72 | H30: =' gsis'!K36 -> 100 | K30: =' gsis'!N36 -> 972.28 | L30: =' gsis'!R36 -> 4846.02 | M30: =' gsis'!S36 -> 2333.33 | N30: =' gsis'!Q36 -> 9634.44 | O30: =' gsis'!P36 -> 1966.67 | P30: =' gsis'!M36 -> 400 | Q30: ='PAG-IBIG'!H53 -> 200 | R30: ='PAG-IBIG'!I53 -> 200 | V30: ='PHIC (1)'!W34 -> 1025.15 | W30: ='PHIC (1)'!X34 -> 1025.15 | X30: =WTAX!H29 -> 3307.28 | Y30: =DBP!G24 -> 5293.1 | AB30: =CNGWMPC!S83 -> 1537.19 | AC30: 2000 | AF30: =E30-F30-I30-J30-K30-L30-M30-N30-O30-P30-Q30-S30-T30-V30-X30-Y30-Z30-AB30+AC30+AD30+AE30 -> 7800 | AG30: 21
A31: 22 | B31: 8711.0-019 | C31: ROWIL B. DIAZ | D31: AG II | E31: =' gsis'!H37 -> 41006 | F31: =' gsis'!I37 -> 3690.54 | G31: =' gsis'!J37 -> 4920.72 | H31: =' gsis'!K37 -> 100 | K31: =' gsis'!N37 -> 0 | L31: =' gsis'!R37 -> 4363.61 | M31: =' gsis'!S37 -> 2333.33 | O31: =' gsis'!P37 -> 0 | P31: =' gsis'!M37 -> 300 | Q31: ='PAG-IBIG'!H54 -> 200 | R31: ='PAG-IBIG'!I54 -> 200 | S31: ='PAG-IBIG'!J54 -> 7517.71 | V31: ='PHIC (1)'!W35 -> 1025.15 | W31: ='PHIC (1)'!X35 -> 1025.15 | X31: =WTAX!H30 -> 3307.28 | AB31: =CNGWMPC!S84 -> 7542.38 | AC31: 2000 | AF31: =E31-F31-I31-J31-K31-L31-M31-N31-O31-P31-Q31-S31-T31-V31-X31-Y31-Z31-AB31+AC31+AD31+AE31 -> 12726 | AG31: 22
A32: 23 | B32: 8711.0-040 | C32: ADOR T. SANCHEZ | D32: AG II | E32: =' gsis'!H38 -> 41006 | F32: =' gsis'!I38 -> 3690.54 | G32: =' gsis'!J38 -> 4920.72 | H32: =' gsis'!K38 -> 100 | Q32: ='PAG-IBIG'!H55 -> 200 | R32: ='PAG-IBIG'!I55 -> 200 | V32: ='PHIC (1)'!W36 -> 1025.15 | W32: ='PHIC (1)'!X36 -> 1025.15 | X32: =WTAX!H31 -> 3307.28 | AB32: =CNGWMPC!S85 -> 7593.03 | AC32: 2000 | AF32: =E32-F32-I32-J32-K32-L32-M32-N32-O32-P32-Q32-S32-T32-V32-X32-Y32-Z32-AB32+AC32+AD32+AE32 -> 27190 | AG32: 23
A33: 24 | B33: 8711.0-049 | C33: JAY Q. CANARIA | D33: AG II | E33: =' gsis'!H39 -> 41006 | F33: =' gsis'!I39 -> 3690.54 | G33: =' gsis'!J39 -> 4920.72 | H33: =' gsis'!K39 -> 100 | K33: =' gsis'!N39 -> 0 | L33: =' gsis'!R39 -> 4563.25 | M33: =' gsis'!S39 -> 2333.33 | N33: =' gsis'!Q39 -> 2272.3 | O33: =' gsis'!P39 -> 1966.67 | P33: =' gsis'!M39 -> 100 | Q33: ='PAG-IBIG'!H56 -> 200 | R33: ='PAG-IBIG'!I56 -> 200 | V33: ='PHIC (1)'!W37 -> 1025.15 | W33: ='PHIC (1)'!X37 -> 1025.15 | X33: =WTAX!H32 -> 3307.28 | AB33: =CNGWMPC!S86 -> 1187.48 | AC33: 2000 | AF33: =E33-F33-I33-J33-K33-L33-M33-N33-O33-P33-Q33-S33-T33-V33-X33-Y33-Z33-AB33+AC33+AD33+AE33 -> 22360 | AG33: 24
A34: 25 | B34: 8711.0-003 | C34: MELINDA L. JEREZ | D34: SA | E34: =' gsis'!H64 -> 80411 | F34: =' gsis'!I64 -> 7236.99 | G34: =' gsis'!J64 -> 9649.32 | H34: =' gsis'!K64 -> 100 | Q34: ='PAG-IBIG'!H57 -> 200 | R34: ='PAG-IBIG'!I57 -> 200 | V34: ='PHIC (1)'!W38 -> 2010.27 | W34: ='PHIC (1)'!X38 -> 2010.28 | X34: =WTAX!H33 -> 12553.53 | AB34: =CNGWMPC!S87 -> 700.21 | AC34: 2000 | AF34: =E34-F34-I34-J34-K34-L34-M34-N34-O34-P34-Q34-S34-T34-V34-X34-Y34-Z34-AB34+AC34+AD34+AE34 -> 59710 | AG34: 25
A35: 26 | B35: 8711.0-043 | C35: RAUL M. CARRIDO | D35: AQ II | E35: =' gsis'!H65 -> 41006 | F35: =' gsis'!I65 -> 3690.54 | G35: =' gsis'!J65 -> 4920.72 | H35: =' gsis'!K65 -> 100 | K35: =' gsis'!N65 -> 1099.53 | L35: =' gsis'!R65 -> 6109.05 | Q35: ='PAG-IBIG'!H58 -> 200 | R35: ='PAG-IBIG'!I58 -> 200 | V35: ='PHIC (1)'!W39 -> 1025.15 | W35: ='PHIC (1)'!X39 -> 1025.15 | X35: =WTAX!H34 -> 3307.28 | AB35: =CNGWMPC!S88 -> 7114.45 | AC35: 2000 | AF35: =E35-F35-I35-J35-K35-L35-M35-N35-O35-P35-Q35-S35-T35-V35-X35-Y35-Z35-AB35+AC35+AD35+AE35 -> 20460 | AG35: 26
A36: 27 | B36: 8711.0-044 | C36: ROWENA V. RAMOS | D36: SR AQ | E36: =' gsis'!H66 -> 51304 | F36: =' gsis'!I66 -> 4617.36 | G36: =' gsis'!J66 -> 6156.48 | H36: =' gsis'!K66 -> 100 | K36: =' gsis'!N66 -> 655.56 | L36: =' gsis'!R66 -> 7636.32 | Q36: ='PAG-IBIG'!H59 -> 200 | R36: ='PAG-IBIG'!I59 -> 200 | V36: ='PHIC (1)'!W40 -> 1282.6 | W36: ='PHIC (1)'!X40 -> 1282.6 | X36: =WTAX!H35 -> 5518.71 | AB36: =CNGWMPC!S89 -> 12483.45 | AC36: 2000 | AF36: =E36-F36-I36-J36-K36-L36-M36-N36-O36-P36-Q36-S36-T36-V36-X36-Y36-Z36-AB36+AC36+AD36+AE36 -> 20910 | AG36: 27
A37: 28 | B37: 8711.0-048 | C37: DESIREE J. RODRIGUEZ | D37: AAQII | E37: =' gsis'!H67 -> 40208 | F37: =' gsis'!I67 -> 3618.72 | G37: =' gsis'!J67 -> 4824.96 | H37: =' gsis'!K67 -> 100 | K37: =' gsis'!N67 -> 0 | L37: =' gsis'!R67 -> 5180.31 | M37: =' gsis'!S67 -> 1400 | O37: =' gsis'!P67 -> 1966.67 | P37: =' gsis'!M67 -> 0 | Q37: ='PAG-IBIG'!H60 -> 200 | R37: ='PAG-IBIG'!I60 -> 200 | V37: ='PHIC (1)'!W41 -> 1005.2 | W37: ='PHIC (1)'!X41 -> 1005.2 | X37: =WTAX!H36 -> 3135.93 | Z37: =LBP!H19 -> 10258.27 | AB37: =CNGWMPC!S90 -> 9609.9 | AC37: 2000 | AF37: =E37-F37-I37-J37-K37-L37-M37-N37-O37-P37-Q37-S37-T37-V37-X37-Y37-Z37-AB37+AC37+AD37+AE37 -> 5833 | AG37: 28
A38: 29 | B38: 8711.0-036 | C38: ISAIAS R. BURAC | D38: SA | E38: =' gsis'!H68 -> 78162 | F38: =' gsis'!I68 -> 7034.58 | G38: =' gsis'!J68 -> 9379.44 | H38: =' gsis'!K68 -> 100 | L38: =' gsis'!R68 -> 8327.94 | O38: =' gsis'!P68 -> 1966.67 | P38: =' gsis'!M68 -> 500 | Q38: ='PAG-IBIG'!H61 -> 200 | R38: ='PAG-IBIG'!I61 -> 200 | V38: ='PHIC (1)'!W42 -> 1954.05 | W38: ='PHIC (1)'!X42 -> 1954.05 | X38: =WTAX!H37 -> 11950.31 | Y38: =DBP!G20 -> 13219.59 | Z38: =LBP!H21 -> 15576.7 | AB38: =CNGWMPC!S91 -> 6422.16 | AC38: 2000 | AF38: =E38-F38-I38-J38-K38-L38-M38-N38-O38-P38-Q38-S38-T38-V38-X38-Y38-Z38-AB38+AC38+AD38+AE38 -> 13010 | AG38: 29
A39: 30 | B39: 8711.0-042 | C39: EFREN D. BALANG | D39: AA III | E39: =' gsis'!H69 -> 16088 | F39: =' gsis'!I69 -> 1447.92 | G39: =' gsis'!J69 -> 1930.56 | H39: =' gsis'!K69 -> 100 | Q39: ='PAG-IBIG'!H62 -> 200 | R39: ='PAG-IBIG'!I62 -> 200 | V39: ='PHIC (1)'!W43 -> 402.2 | W39: ='PHIC (1)'!X43 -> 402.2 | AB39: =CNGWMPC!S92 -> 4587.88 | AC39: 2000 | AF39: =E39-F39-I39-J39-K39-L39-M39-N39-O39-P39-Q39-S39-T39-V39-X39-Y39-Z39-AB39+AC39+AD39+AE39 -> 11450 | AG39: 30
A40: 31 | B40: 8711.0-046 | C40: GERRY Y. ECHANO | D40: AA III | E40: =' gsis'!H70 -> 16088 | F40: =' gsis'!I70 -> 1447.92 | G40: =' gsis'!J70 -> 1930.56 | H40: =' gsis'!K70 -> 100 | Q40: ='PAG-IBIG'!H63 -> 200 | R40: ='PAG-IBIG'!I63 -> 200 | V40: ='PHIC (1)'!W44 -> 402.2 | W40: ='PHIC (1)'!X44 -> 402.2 | AB40: =CNGWMPC!S93 -> 747.88 | AC40: 2000 | AF40: =E40-F40-I40-J40-K40-L40-M40-N40-O40-P40-Q40-S40-T40-V40-X40-Y40-Z40-AB40+AC40+AD40+AE40 -> 15290 | AG40: 31
...

Sheet  gsis
G8: OFFICE OF THE PROVINCIAL AGRICULTURIST
B10: GOVERNMENT SERVICE INSURANCE SYSTEM CONTRIBUTION REMITTANCE
B11: For the period covered FEBRUARY 2026
I13: LIFE/RETIREMENT
A14: NO. | B14: LAST NAME | C14: FIRST NAME | D14: MIDDLE NAME | E14: NAME | F14: BIRTHDATE | G14: GSIS | H14: BASIC | I14: INSURANCE CONTRIBUTION | M14: POLICY | N14: EMERGENCY | O14: REAL STATE | P14: COMPUTER
E15: EXT. | G15: NUMBER | H15: SALARY | I15: PS | J15: GS | K15: ECF | L15: CONSOLOAN | M15: LOAN | N15: LOAN | O15: LOAN | P15: LOAN | Q15: GFAL | R15: MPL | S15: MPL LITE
A16: 1 | B16: ABAD | C16: ALMIRANTE | D16: ANDAYA | F16: 25309 | G16: 2001333753 | H16: 132280 | I16: =H16*0.09 -> 11905.2 | J16: =H16*0.12 -> 15873.6 | K16: 100
A17: 2 | B17: BELARDO | C17: RAPHY | D17: BASQUIÑAS | F17: 27998 | G17: 2001337619 | H17: 81564 | I17: =H17*0.09 -> 7340.76 | J17: =H17*0.12 -> 9787.68 | K17: 100 | Q17: 9634.44 | R17: 12189.13 | S17: 2333.33
A18: 3 | B18: NASOL | C18: MARIA GISELA | D18: CENETA | F18: 26680 | G18: 2001341176 | H18: 78162 | I18: =H18*0.09 -> 7034.58 | J18: =H18*0.12 -> 9379.44 | K18: 100 | P18: 1966.67 | Q18: 9634.44 | R18: 12177.29 | S18: 2333.33
A19: 4 | B19: CERENO | C19: MARLENE | D19: VALENCIA | F19: 33118 | G19: 2004721100 | H19: 41413 | I19: =H19*0.09 -> 3727.17 | J19: =H19*0.12 -> 4969.56 | K19: 100 | M19: 300 | N19: 655.56 | P19: 1966.67 | R19: 4408.9 | S19: 2333.33
A20: 5 | B20: BARCELONA | C20: MELINDA | D20: RAMOS | F20: 23889 | G20: 2001341502 | H20: 51304 | I20: =H20*0.09 -> 4617.36 | J20: =H20*0.12 -> 6156.48 | K20: 100 | M20: 200 | P20: 1966.67 | Q20: 9634.44 | R20: 7992.93 | S20: 2333.33
A21: 6 | B21: OBUSAN | C21: ELNORA | D21: BANAL | F21: 26324 | G21: 2001339696 | H21: 38118 | I21: =H21*0.09 -> 3430.62 | J21: =H21*0.12 -> 4574.16 | K21: 100 | M21: 200 | N21: 1311.12 | R21: 6298.92
A22: 7 | B22: DE JESUS | C22: EDWIN | D22: VALERIO | F22: 28404 | G22: 2003905771 | H22: 41006 | I22: =H22*0.09 -> 3690.54 | J22: =H22*0.12 -> 4920.72 | K22: 100 | P22: 1966.67 | R22: 6109.05 | S22: 1866.67
A23: 8 | B23: MAGANA | C23: GLENDA | D23: MEDRANO | F23: 25553 | G23: 2004730585 | H23: 17209 | I23: =H23*0.09 -> 1548.81 | J23: =H23*0.12 -> 2065.08 | K23: 100 | P23: 1966.67 | Q23: 5603.77 | R23: 2236.76
A24: 9 | B24: VELACRUZ | C24: PEDRO | D24: SENTIN | E24: III | F24: 26265 | G24: 2001337337 | H24: 18133 | I24: =H24*0.09 -> 1631.97 | J24: =H24*0.12 -> 2175.96 | K24: 100 | R24: 2848.19
A25: 10 | B25: ARCIGA | C25: SALLY | D25: REYES | F25: 28312 | G25: 2005606123 | H25: 16088 | I25: =H25*0.09 -> 1447.92 | J25: =H25*0.12 -> 1930.56 | K25: 100 | M25: 100 | N25: 655.56 | P25: 1966.67 | R25: 2074.66
A26: 11 | B26: QUIBRAL | C26: MACK LENNON | D26: GONZALES | F26: 35129 | G26: 2005606047 | H26: 25996 | I26: =H26*0.09 -> 2339.64 | J26: =H26*0.12 -> 3119.52 | K26: 100 | M26: 200 | R26: 3467.78 | S26: 1816.67
A27: 12 | B27: JAUCIAN | C27: GEMMA | D27: SABULARCE | F27: 24970 | G27: 2005606078 | H27: 20408 | I27: =H27*0.09 -> 1836.72 | J27: =H27*0.12 -> 2448.96 | K27: 100 | M27: 200 | N27: 655.56 | P27: 1966.67 | R27: 2631.62
A28: 13 | B28: DORIMAN | C28: DULCE | D28: DELFINO | F28: 28367 | G28: 2001332798 | H28: 52367 | I28: =H28*0.09 -> 4713.03 | J28: =H28*0.12 -> 6284.04 | K28: 100 | N28: 1138.73 | O28: 1533.5 | Q28: 9634.44 | R28: 7801.77 | S28: 2333.33
A29: 14 | B29: MALALUAN | C29: SANTIAGO | D29: GONZALES | F29: 22487 | G29: 2001338398 | H29: 43090 | I29: =H29*0.09 -> 3878.1 | J29: =H29*0.12 -> 5170.8 | K29: 100 | M29: 500 | Q29: 9634.44 | R29: 6433.73
A30: 15 | B30: SALVANERA | C30: CELESTE | D30: MAGO | F30: 30185 | G30: 2001332731 | H30: 51304 | I30: =H30*0.09 -> 4617.36 | J30: =H30*0.12 -> 6156.48 | K30: 100 | M30: 100 | Q30: 9634.44
A31: 16 | B31: CLACIO | C31: ALGEM MARIE | D31: JAUCIAN | F31: 34606 | G31: 2005606098 | H31: 37024 | I31: =H31*0.09 -> 3332.16 | J31: =H31*0.12 -> 4442.88 | K31: 100 | P31: 1966.67
A32: 17 | B32: PALAD | C32: CHRISTINE | D32: LOLOS | F32: 35890 | G32: 2005606118 | H32: 25996 | I32: =H32*0.09 -> 2339.64 | J32: =H32*0.12 -> 3119.52 | K32: 100
A33: 18 | B33: MIRAÑA | C33: CESAR | D33: REMETIR | F33: 22351 | G33: 2001308130 | H33: 52367 | I33: =H33*0.09 -> 4713.03 | J33: =H33*0.12 -> 6284.04 | K33: 100
A34: 19 | B34: MENESES | C34: BRENDA | D34: RELANO | F34: 29908 | G34: 2004617188 | H34: 41413 | I34: =H34*0.09 -> 3727.17 | J34: =H34*0.12 -> 4969.56 | K34: 100 | Q34: 9634.44 | R34: 4408.9 | S34: 2333.33
A35: 20 | B35: ASIS | C35: RONNIE | D35: RIVERA | F35: 27392 | G35: 2001338301 | H35: 42241 | I35: =H35*0.09 -> 3801.69 | J35: =H35*0.12 -> 5068.92 | K35: 100 | Q35: 9634.44 | R35: 7823.43
A36: 21 | B36: VILLAFLORES | C36: RYAN | D36: IBANA | F36: 29471 | G36: 2004315758 | H36: 41006 | I36: =H36*0.09 -> 3690.54 | J36: =H36*0.12 -> 4920.72 | K36: 100 | M36: 400 | N36: 972.28 | P36: 1966.67 | Q36: 9634.44 | R36: 4846.02 | S36: 2333.33
A37: 22 | B37: DIAZ | C37: ROWIL | D37: BELANTE | F37: 25794 | G37: 2004617189 | H37: 41006 | I37: =H37*0.09 -> 3690.54 | J37: =H37*0.12 -> 4920.72 | K37: 100 | M37: 300 | R37: 4363.61 | S37: 2333.33
A38: 23 | B38: SANCHEZ | C38: ADOR | D38: TERCERO | F38: 28448 | G38: 2005170627 | H38: 41006 | I38: =H38*0.09 -> 3690.54 | J38: =H38*0.12 -> 4920.72 | K38: 100
A39: 24 | B39: CANARIA | C39: JAY | D39: QUINITO | F39: 33010 | G39: 2004297137 | H39: 41006 | I39: =H39*0.09 -> 3690.54 | J39: =H39*0.12 -> 4920.72 | K39: 100 | M39: 100 | P39: 1966.67 | Q39: 2272.3 | R39: 4563.25 | S39: 2333.33
B40: PAGE TOTAL | H40: =SUM(H16:H39) -> 1071507 | I40: =SUM(I16:I39) -> 96435.63 | J40: =SUM(J16:J39) -> 128580.84 | K40: =SUM(K16:K39) -> 2400 | L40: =SUM(L16:L39) -> 0 | M40: =SUM(M16:M39) -> 2600 | N40: =SUM(N16:N39) -> 5388.81 | O40: =SUM(O16:O39) -> 1533.5 | ... S40: =SUM(S16:S39) -> 24683.31
O47: p
G54: OFFICE OF THE PROVINCIAL AGRICULTURIST
B56: GOVERNMENT SERVICE INSURANCE SYSTEM CONTRIBUTION REMITTANCE
B57: For the period covered FEBRUARY 2026
I61: LIFE/RETIREMENT
A62: NO. | B62: LAST NAME | C62: FIRST NAME | D62: MIDDLE NAME | E62: NAME | F62: BIRTHDATE | G62: GSIS | H62: BASIC | I62: INSURANCE CONTRIBUTION | L62: CONSO | M62: POLICY | N62: EMERGENCY | O62: REAL STATE | P62: COMPUTER
E63: EXT. | G63: NUMBER | H63: SALARY | I63: PS | J63: GS | K63: ECF | L63: LOAN | M63: LOAN | N63: LOAN | O63: LOAN | P63: LOAN | Q63: GFAL | R63: MPL | S63: MPL LITE
A64: 25 | B64: JEREZ | C64: MELINDA | D64: LAGATUZ | F64: 22944 | G64: 2001341487 | H64: 80411 | I64: =H64*0.09 -> 7236.99 | J64: =H64*0.12 -> 9649.32 | K64: 100
A65: 26 | B65: CARRIDO | C65: RAUL | D65: MORENO | F65: 22990 | G65: 2001306774 | H65: 41006 | I65: =H65*0.09 -> 3690.54 | J65: =H65*0.12 -> 4920.72 | K65: 100 | N65: 1099.53 | R65: 6109.05
...

Sheet PAG-IBIG
C7: OFFICE OF THE PROVINCIAL AGRICULTURIST
A9: PAG IBIG FUND CONTRIBUTION REMITTANCE
A10: For the period covered FEBRUARY 2026
A11: p
A12: NO. | B12: LAST NAME | C12: FIRST NAME | D12: MIDDLE | E12: NAME | F12: BIRTHDATE | G12: PAG IBIG | H12: EMPLOYEE | I12: EMPLOYER | J12: MPL | K12: CALAMITY | L12: HOUSING | M12: MP 2
E13: EXT. | G13: MID NO. | H13: SHARE | I13: SHARE | K13: LOAN | L13: LOAN
A14: 1 | B14: ABAD | C14: ALMIRANTE | D14: ANDAYA | F14: 25309 | G14: 1530-0094-2026 | H14: 2000 | I14: 200
A15: 2 | B15: BELARDO | C15: RAPHY | D15: BASQUIŇAS | F15: 27998 | G15: 1530-0094-1763 | H15: 500 | I15: 200
A16: 3 | B16: NASOL | C16: MARIA GISELA | D16: CENETA | F16: 26680 | G16: 1530-0094-2873 | H16: 700 | I16: 200 | J16: 1500
A17: 4 | B17: CERENO | C17: MARLENE | D17: VALENCIA | F17: 33118 | G17: 1210-7742-9143 | H17: 200 | I17: 200
A18: 5 | B18: BARCELONA | C18: MELINDA | D18: RAMOS | F18: 23889 | G18: 1530-0093-7375 | H18: 400 | I18: 200
A19: 6 | B19: OBUSAN | C19: ELNORA | D19: BANAL | F19: 26324 | G19: 1530-0094-2550 | H19: 500 | I19: 200
A20: 7 | B20: DE JESUS | C20: EDWIN | D20: VALERIO | F20: 28404 | G20: 1210-0494-8719 | H20: 200 | I20: 200
A21: 8 | B21: MAGANA | C21: GLENDA | D21: MEDRANO | F21: 25553 | G21: 1211-1103-7552 | H21: 400 | I21: 200
A22: 9 | B22: VELACRUZ | C22: PEDRO | D22: SENTIN | E22: III | F22: 26265 | G22: 0502-2892-8211 | H22: 200 | I22: 200
A23: 10 | B23: ARCIGA | C23: SALLY | D23: REYES | F23: 28312 | G23: 1210-6771-3642 | H23: 200 | I23: 200
A24: 11 | B24: QUIBRAL | C24: MACK LENNON | D24: GONZALES | F24: 35129 | G24: 1212-1574-6170 | H24: 200 | I24: 200
A25: 12 | B25: JAUCIAN | C25: GEMMA | D25: SABULARCE | F25: 24970 | G25: 1210-6759-2203 | H25: 200 | I25: 200 | K25: 970.5
A26: 13 | B26: DORIMAN | C26: DULCE | D26: DELFINO | F26: 28367 | G26: 1530-0094-2349 | H26: 200 | I26: 200
A27: 14 | B27: MALALUAN | C27: SANTIAGO | D27: GONZALES | F27: 22487 | G27: 1530-0093-9273 | H27: 200 | I27: 200
A28: 15 | B28: SALVANERA | C28: CELESTE | D28: MAGO | F28: 30185 | G28: 1530-0094-3431 | H28: 200 | I28: 200
A29: 16 | B29: CLACIO | C29: ALGEM MARIE | D29: JAUCIAN | F29: 34606 | G29: 1211-6779-8483 | H29: 200 | I29: 200
A30: 17 | B30: PALAD | C30: CHRISTINE | D30: LOBOS | F30: 35890 | G30: 1212-3179-5813 | H30: 200 | I30: 200
H31: =SUM(H14:H30) -> 6700 | I31: =SUM(I14:I30) -> 3400 | J31: =SUM(J14:J30) -> 1500 | K31: =SUM(K14:K30) -> 970.5
D32: TOTAL | H32: =SUM(H31) -> 6700 | I32: =SUM(I31) -> 3400 | J32: =SUM(J31) -> 1500 | K32: =SUM(K31) -> 970.5
C43: OFFICE OF THE PROVINCIAL AGRICULTURIST
A45: PAG IBIG FUND CONTRIBUTION REMITTANCE
A46: For the period covered FEBRUARY 2026
A48: NO. | B48: LAST NAME | C48: FIRST NAME | D48: MIDDLE | E48: NAME | F48: BIRTHDATE | G48: PAG IBIG | H48: EMPLOYEE | I48: EMPLOYER | J48: MPL | K48: CALAMITY | L48: HOUSING | M48: MP 2
E49: EXT. | G49: MID NO. | H49: SHARE | I49: SHARE | K49: LOAN | L49: LOAN
A50: 18 | B50: MIRAŇA | C50: CESAR | D50: REMETIR | F50: 22351 | G50: 0502-1435-1803 | H50: 200 | I50: 200
A51: 19 | B51: MENESES | C51: BRENDA | D51: RELANO | F51: 29908 | G51: 1210-0832-1069 | H51: 200 | I51: 200
A52: 20 | B52: ASIS | C52: RONNIE | D52: RIVERA | F52: 27392 | G52: 1530-0094-2849 | H52: 200 | I52: 200
A53: 21 | B53: VILLAFLORES | C53: RYAN | D53: IBANA | F53: 29471 | G53: 1211-0797-5538 | H53: 200 | I53: 200
A54: 22 | B54: DIAZ | C54: ROWIL | D54: BELANTE | F54: 25794 | G54: 1530-0092-6463 | H54: 200 | I54: 200 | J54: 7517.71
A55: 23 | B55: SANCHEZ | C55: ADOR | D55: TERCERO | F55: 28448 | G55: 1211-9355-8310 | H55: 200 | I55: 200
A56: 24 | B56: CANARIA | C56: JAY | D56: QUINITO | F56: 33010 | G56: 1210-6456-0488 | H56: 200 | I56: 200
A57: 25 | B57: JEREZ | C57: MELINDA | D57: LAGATUZ | F57: 22944 | G57: 1530-0093-8928 | H57: 200 | I57: 200
A58: 26 | B58: CARRIDO | C58: RAUL | D58: MORENO | F58: 22990 | G58: 1530-0002-8136 | H58: 200 | I58: 200
A59: 27 | B59: RAMOS | C59: ROWENA | D59: VILLALUNA | F59: 23033 | G59: 1530-0011-7259 | H59: 200 | I59: 200
...

Sheet WTAX
C7: OFFICE OF THE PROVINCIAL AGRICULTURIST
C9: STATEMENT OF REMITTANCE FOR WITHHOLDING TAX
C10: For the period covered FEBRUARY 2026
E12: NAME
A13: No. | B13: LAST NAME | C13: FIRST NAME | D13: MIDDLE NAME | E13: EXT. | F13: BIRTHDAY | G13: T.I.N | H13: AMOUNT
A14: 1 | B14: ABAD | C14: ALMIRANTE | D14: ANDAYA | F14: 25309 | G14: 917-883-499 | H14: 26527.12
A15: 2 | B15: BELARDO | C15: RAPHY | D15: BASQUIÑAS | F15: 27998 | G15: 920-897-958 | H15: 12862.52
A16: 3 | B16: NASOL | C16: MARIA GISELA | D16: CENETA | F16: 26680 | G16: 177-725-719 | H16: 11950.31
A17: 4 | B17: CERENO | C17: MARLENE | D17: VALENCIA | F17: 33118 | G17: 455-545-593 | H17: 3394.69
A18: 5 | B18: BARCELONA | C18: MELINDA | D18: RAMOS | F18: 23889 | G18: 194-250-448 | H18: 5518.71
A19: 6 | B19: OBUSAN | C19: ELNORA | D19: BANAL | F19: 26324 | G19: 184-991-548 | H19: 2597.29
A20: 7 | B20: DE JESUS | C20: EDWIN | D20: VALERIO | F20: 28404 | G20: 934-370-349 | H20: 3307.28
A21: 8 | B21: QUIBRAL | C21: MACK LENNON | D21: GONZALES | F21: 35129 | G21: 331-015-003 | H21: 537
A22: 9 | B22: DORIMAN | C22: DULCE | D22: DELFINO | F22: 28367 | G22: 923-151-932 | H22: 5746.98
A23: 10 | B23: MALALUAN | C23: SANTIAGO | D23: GONZALES | F23: 22487 | G23: 115-112-217 | H23: 204.04
A24: 11 | B24: SALVANERA | C24: CELESTE | D24: MAGO | F24: 30185 | G24: 944-445-062 | H24: 5518.71
A25: 12 | B25: CLACIO | C25: ALGEM MARIE | D25: JAUCIAN | F25: 34606 | G25: 478-090-392 | H25: 2302.93
... A40: 27 | B40: DELA CRUZ | C40: ALEXIS | D40: RAFAEL | F40: 33073 | G40: 732-844-188 | H40: 3145.93
G46: TOTAL | H46: =SUM(H14:H40) -> 145589.86
B50: Prepared by: | F50: Certified Correct:
B53: MELINDA R. BARCELONA | F53: ALMIRANTE A. ABAD
B54: Admin. Officer V | F54: Provincial Agriculturist

Sheet DBP
B7: OFFICE OF THE PROVINCIAL AGRICULTURIST
B9: DEVELOPMENT BANK OF THE PHILIPPINES (DBP) LOAN AMORTIZATION REMITTANCE
B10: For the period covered FEBRUARY 2026
B14: MARIA GISELA C. NASOL
A15: NO. | B15: LAST NAME | C15: FIRST NAME | D15: MIDDLE NAME | E15: NAME EXT. | F15: BIRTHDATE | G15: AMOUNT DUE
A16: 1 | B16: OBUSAN | C16: ELNORA | D16: BANAL | F16: 26324 | G16: 7900.15
A17: 2 | B17: NASOL | C17: MARIA GISELA | D17: CENETA | F17: 26680 | G17: 2633.38
A18: 3 | B18: BARCELONA | C18: MELINDA | D18: RAMOS | F18: 23889 | G18: 5266.77
A19: 4 | B19: BELARDO | C19: RAPHY | D19: BASQUIÑAS | F19: 27998 | G19: 14483.61
A20: 5 | B20: BURAC | C20: ISAIAS | D20: REAMBON | F20: 32178 | G20: 13219.59
A21: 6 | B21: ARCIGA | C21: SALLY | D21: REYES | F21: 28312 | G21: 5266.77
A22: 7 | B22: JAUCIAN | C22: GEMMA | D22: SABULARCE | F22: 24970 | G22: 6583.46
A23: 8 | B23: QUIBRAL | C23: MACK LENNON | D23: GONZALES | F23: 35129 | G23: 4356.07
A24: 9 | B24: VILLAFLORES | C24: RYAN | D24: IBANA | F24: 29471 | G24: 5293.1
A25: 10 | B25: DORIMAN | C25: DULCE | D25: DELFINO | F25: 28367 | G25: 6263.95
F31: TOTAL | G31: =SUM(G16:G26) -> 71266.85
B35: Prepared by: | E35: Certified Correct:
B38: MELINDA R. BARCELONA | E38: ALMIRANTE A. ABAD
B39: Administrative Officer V | E39: Provinical Agriculturist

Sheet PARACLE
C7: OFFICE OF THE PROVINCIAL AGRICULTURIST
C9: RURAL BANK OF PARACALE LOAN AMORTIZATION REMITTANCE
C10: For theperiod covered JULY 2025
B15: NO. | C15: LAST NAME | D15: FIRST NAME | E15: MIDDLE NAME | F15: NAME EXT. | G15: BIRTHDATE | H15: AMOUNT DUE
A17: 1 | B17: 1 | C17: QUIJANO | D17: HELEN | E17: REYES | G17: 24685
G21: Jay Q. Canaria
G22: TOTAL | H22: =SUM(H15:H21) -> 0
C24: Prepared by: | F24: Certified Correct:
C27: MELINDA R. BARCELONA | F27: ALMIRANTE A. ABAD
C28: Administrative Officer V | F28: Provincial Agriculturist
G51: Republic of the Philippines
G52: PROVINCE OF CAMARINES NORTE
G53: D a e t
G55: OFFICE OF THE PROVINCIAL AGRICULTURIST
G57: REMITTANCE STATEMENT FOR LBP
A58: For the Month of JANUARY 2022
G60: NAME OF EMPLOYEE | H60: AMOUNT
G62: Raphy B. Belardo
A64: 1 | G64: RAPHY B. BELARDO | H64: 9964.29
G65: Orlando V. Asis | H65: 3886.07
G66: Ryan I. Villaflores
A67: 2 | G67: Renato M. Magana
A69: 3
A70: 4
G77: TOTAL | H77: =SUM(H62:H76) -> 13850.36
H81: Prepared by:
H84: MELINDA R. BARCELONA
H85: Administrative Officer III

Sheet LBP
C7: OFFICE OF THE PROVINCIAL AGRICULTURIST
C9: LAND BANK OF THE PHILIPPINES (LBP) LOAN AMORTIZATION REMITTANCE
C10: For theperiod covered FEBRUARY 2026
B15: NO. | C15: LAST NAME | D15: FIRST NAME | E15: MIDDLE NAME | F15: NAME EXT. | G15: BIRTHDATE | H15: AMOUNT DUE
A17: 1 | B17: 1 | C17: DE JESUS | D17: EDWIN | E17: VALERIO | G17: 28404 | H17: 16413.23
B18: 2 | C18: QUIBRAL | D18: MACK LENNON | E18: GONZALES | G18: 35129 | H18: 3788.1
B19: 3 | C19: RODRIGUEZ | D19: DESIREE | E19: JABINES | G19: 35258 | H19: 10258.27
B20: 4 | C20: NASOL | D20: MARIA GISELA | E20: CENETA | G20: 26680 | H20: 15756.7
B21: 5 | C21: BURAC | D21: ISAIAS | E21: REAMBON | G21: 32178 | H21: 15576.7
B22: 6 | C22: QUIJANO | D22: HELEN | E22: REYES | G22: 24685 | H22: 4577.29
G23: TOTAL | H23: =SUM(H15:H22) -> 66370.29
C25: Prepared by: | F25: Certified Correct:
C28: MELINDA R. BARCELONA | F28: ALMIRANTE A. ABAD
C29: Administrative Officer V | F29: Provincial Agriculturist
G52: Republic of the Philippines
G53: PROVINCE OF CAMARINES NORTE
G54: D a e t
G56: OFFICE OF THE PROVINCIAL AGRICULTURIST
G58: REMITTANCE STATEMENT FOR LBP
A59: For the Month of JANUARY 2022
G61: NAME OF EMPLOYEE | H61: AMOUNT
G63: Raphy B. Belardo
A65: 1 | G65: RAPHY B. BELARDO | H65: 9964.29
G66: Orlando V. Asis | H66: 3886.07
G67: Ryan I. Villaflores
A68: 2 | G68: Renato M. Magana
A70: 3
A71: 4
G78: TOTAL | H78: =SUM(H63:H77) -> 13850.36
H82: Prepared by:
H85: MELINDA R. BARCELONA
H86: Administrative Officer III

Sheet CNGWMPC
A6: OFFICE OF THE PROVINCIAL AGRICULTURIST
H8: CNGWMPC REMITTANCE
H9: For the period covered FEBRUARY 2026
A11: NO | C11: FIRST NAME | D11: MIDDLE NAME | E11: NAME EXT. | I11: REGULAR LOAN | J11: IN CRISIS LOAN | K11: Coop Canteen | N11: ABULOY PROGRAM | O11: HANDOG KABUHAYAN/ITURO MO | P11: BACK TO BACK LOAN/SPECIAL LOAN | Q11: PETTY CASH | S11: TOTAL DUE
B12: LAST NAME | L12: Coop | M12: CALAMITY | R12: COMMODITY
F13: CAPITAL SHARE | G13: KIDDIE | H13: SAVINGS | L13: Store | M13: LOAN | R13: LOAN
G14: SAVINGS
A15: 1 | B15: ABAD | C15: ALMIRANTE | D15: ANDAYA | F15: 1007.68 | H15: 25000 | K15: 100 | N15: 300 | S15: =F15+H15+I15+J15+K15+L15+M15+N15+O15+P15+Q15+R15 -> 26407.68
A16: 2 | B16: BELARDO | C16: RAPHY | D16: BASQUIÑAS | F16: 401.11 | N16: 300 | S16: =F16+H16+I16+J16+K16+L16+M16+N16+O16+P16+Q16+R16 -> 701.11
A17: 3 | B17: NASOL | C17: MARIA GISELA | D17: CENETA | F17: 406.25 | N17: 300 | O17: 2425 | S17: =F17+H17+I17+J17+K17+L17+M17+N17+O17+P17+Q17+R17 -> 3131.25
A18: 4 | B18: CERENO | C18: MARLENE | D18: VALENCIA | F18: 401.36 | H18: 500 | N18: 300 | Q18: 100 | S18: =F18+H18+I18+J18+K18+L18+M18+N18+O18+P18+Q18+R18 -> 1301.36
A19: 5 | B19: BARCELONA | C19: MELINDA | D19: RAMOS | F19: 401.19 | K19: 340 | L19: 417 | M19: 1413 | N19: 300 | Q19: 100 | S19: =F19+H19+I19+J19+K19+L19+M19+N19+O19+P19+Q19+R19 -> 2971.19
A20: 6 | B20: OBUSAN | C20: ELNORA | D20: BANAL | F20: 400.45 | I20: 5200 | L20: 756.5 | N20: 300 | Q20: 100 | S20: =F20+H20+I20+J20+K20+L20+M20+N20+O20+P20+Q20+R20 -> 6756.95
A21: 7 | B21: DE JESUS | C21: EDWIN | D21: VALERIO | F21: 407.41 | N21: 300 | S21: =F21+H21+I21+J21+K21+L21+M21+N21+O21+P21+Q21+R21 -> 707.41
A22: 8 | B22: MAGANA | C22: GLENDA | D22: MEDRANO | F22: 402.77 | N22: 300 | S22: =F22+H22+I22+J22+K22+L22+M22+N22+O22+P22+Q22+R22 -> 702.77
A23: 9 | B23: VELACRUZ | C23: PEDRO | D23: SENTIN | E23: III | F23: 401.52 | I23: 5354 | N23: 300 | Q23: 98 | S23: =F23+H23+I23+J23+K23+L23+M23+N23+O23+P23+Q23+R23 -> 6153.52
A24: 10 | B24: ARCIGA | C24: SALLY | D24: REYES | F24: 404.22 | N24: 300 | Q24: 100 | S24: =F24+H24+I24+J24+K24+L24+M24+N24+O24+P24+Q24+R24 -> 804.22
A25: 11 | B25: QUIBRAL | C25: MACK LENNON | D25: GONZALES | F25: 400.84 | N25: 300 | Q25: 100 | S25: =F25+H25+I25+J25+K25+L25+M25+N25+O25+P25+Q25+R25 -> 800.84
A26: 12 | B26: JAUCIAN | C26: GEMMA | D26: SABULARCE | F26: 503.27 | H26: 500 | N26: 300 | Q26: 80 | S26: =F26+H26+I26+J26+K26+L26+M26+N26+O26+P26+Q26+R26 -> 1383.27
A27: 13 | B27: DORIMAN | C27: DULCE | D27: DELFINO | F27: 402.1 | N27: 300 | Q27: 200 | S27: =F27+H27+I27+J27+K27+L27+M27+N27+O27+P27+Q27+R27 -> 902.1
A28: 14 | B28: MALALUAN | C28: SANTIAGO | D28: GONZALES | F28: 408.44 | I28: 4002 | M28: 942 | N28: 300 | Q28: 40 | S28: =F28+H28+I28+J28+K28+L28+M28+N28+O28+P28+Q28+R28 -> 5692.44
A29: 15 | B29: SALVANERA | C29: CELESTE | D29: MAGO | F29: 400.89 | N29: 300 | Q29: 100 | S29: =F29+H29+I29+J29+K29+L29+M29+N29+O29+P29+Q29+R29 -> 800.89
A30: 16 | B30: CLACIO | C30: ALGEM MARIE | D30: JAUCIAN | F30: 402.64 | G30: 500 | H30: 500 | I30: 5820 | M30: 942 | N30: 300 | O30: 2182 | S30: =F30+H30+I30+J30+K30+L30+M30+N30+O30+P30+Q30+R30+G30 -> 10646.64
A31: 17 | B31: PALAD | C31: CHRISTINE | D31: LOLOS | F31: 409.54 | H31: 1000 | N31: 300 | Q31: 89.92 | S31: =F31+H31+I31+J31+K31+L31+M31+N31+O31+P31+Q31+R31 -> 1799.46
A32: 18 | B32: MIRAÑA | C32: CESAR | D32: REMETIR | F32: 101.8 | I32: 17333 | N32: 300 | S32: =F32+H32+I32+J32+K32+L32+M32+N32+O32+P32+Q32+R32 -> 17734.8
A33: 19 | B33: MENESES | C33: BRENDA | D33: RELANO | F33: 402.15 | H33: 1000 | I33: 7137 | N33: 300 | S33: =F33+H33+I33+J33+K33+L33+M33+N33+O33+P33+Q33+R33 -> 8839.15
A34: 20 | B34: ASIS | C34: RONNIE | D34: RIVERA | F34: 402.98 | N34: 300 | S34: =F34+H34+I34+J34+K34+L34+M34+N34+O34+P34+Q34+R34 -> 702.98
D35: Sub-total | F35: =SUM(F15:F34) -> 8468.61 | G35: =SUM(G15:G34) -> 500 | H35: =SUM(H15:H34) -> 28500 | I35: =SUM(I15:I34) -> 44846 | J35: =SUM(J15:J34) -> 0 | K35: =SUM(K15:K34) -> 440 | L35: =SUM(L15:L34) -> 1173.5 | M35: =SUM(M15:M34) -> 3297 | ... R35: =SUM(R15:R34) -> 0 | S35: =F35+G35+H35+I35+J35+K35+L35+M35+N35+O35+P35+Q35+R35 -> 98940.03
I71: OFFICE OF THE PROVINCIAL AGRICULTURIST
I73: CNGWMPC REMITTANCE
A74: For the period covered FEBRUARY 2026
A79: NO | D79: MIDDLE NAME | E79: NAME EXT. | I79: REGULAR LOAN | J79: IN CRISIS LOAN | K79: Coop Canteen | N79: ABULOY PROGRAM | O79: HANDOG KABUHAYAN/ITURO MO | P79: BACK TO BACK LOAN/SPECIAL LOAN | Q79: PETTY CASH | S79: TOTAL DUE
B80: LAST NAME | C80: FIRST NAME | M80: CALAMITY | R80: COMMODITY
F81: CAPITAL SHARE | G81: kiddie | H81: SAVINGS | L81: Coop | M81: LOAN | R81: LOAN
G82: savings | L82: Store
A83: 21 | B83: VILLAFLORES | C83: RYAN | D83: IBANA | F83: 409.04 | H83: 500 | L83: 228.15 | N83: 300 | Q83: 100 | S83: =F83+H83+I83+J83+K83+L83+M83+N83+O83+P83+Q83+R83 -> 1537.19
A84: 22 | B84: DIAZ | C84: ROWIL | D84: BELANTE | F84: 406.38 | I84: 2774 | J84: 2708 | N84: 300 | O84: 1354 | S84: =F84+H84+I84+J84+K84+L84+M84+N84+O84+P84+Q84+R84 -> 7542.38
A85: 23 | B85: SANCHEZ | C85: ADOR | D85: TERCERO | F85: 406.03 | I85: 6787 | N85: 300 | Q85: 100 | S85: =F85+H85+I85+J85+K85+L85+M85+N85+O85+P85+Q85+R85 -> 7593.03
A86: 24 | B86: CANARIA | C86: JAY | D86: QUINITO | F86: 400.48 | L86: 387 | N86: 300 | Q86: 100 | S86: =F86+H86+I86+J86+K86+L86+M86+N86+O86+P86+Q86+R86 -> 1187.48
A87: 25 | B87: JEREZ | C87: MELINDA | D87: LAGATUZ | F87: 400.21 | N87: 300 | S87: =F87+H87+I87+J87+K87+L87+M87+N87+O87+P87+Q87+R87 -> 700.21
...

Sheet PAYSLIP
A1: Republic of the Philippines | E1: Republic of the Philippines
A2: PROVINCE OF CAMARINES NORTE | E2: PROVINCE OF CAMARINES NORTE
A3: D A E T | E3: D A E T
A4: OFFICE OF THE PROVINCIAL AGRICULTURIST | E4: OFFICE OF THE PROVINCIAL AGRICULTURIST
A5: PAY SLIP | E5: PAY SLIP
A6: Name | B6: ='payroll(FEB)'!C10 -> ALMIRANTE A. ABAD | E6: Name | F6: ='payroll(FEB)'!C11 -> RAPHY B. BELARDO
A7: Position | B7: ='payroll(FEB)'!D10 -> PA | E7: Position | F7: PO IV
A8: For the Period | B8: 2/1-28/2026 | E8: For the Period | F8: 2/1-28/2026
A9: Gross Salary | C9: ='payroll(FEB)'!E10 -> 132280 | E9: Gross Salary | G9: ='payroll(FEB)'!E11 -> 81564
A10: PERA/RA/TA | C10: ='payroll(FEB)'!AC10+'payroll(FEB)'!AD10+'payroll(FEB)'!AE10 -> 21000 | E10: PERA | G10: ='payroll(FEB)'!AC11 -> 2000
A11: Less Deduction | E11: Less Deduction
A12: UCPB | E12: UCPB
A13: MPL | E13: MPL
A14: CBCN | E14: CBCN
A15: MSLAP | E15: MSLAP
A16: Withholding Tax | C16: =WTAX!H14 -> 26527.12 | E16: Withholding Tax | G16: =WTAX!H15 -> 12862.52
A17: GSIS salary Loan | E17: GSIS salary Loan
A18: GSIS Policy Loan | E18: GSIS Policy Loan
A19: Medicare | C19: ='PHIC (1)'!W14 -> 2500 | E19: Medicare | G19: ='PHIC (1)'!W15 -> 2039.1
A20: GSIS Premium | C20: =' gsis'!I16 -> 11905.2 | E20: GSIS Premium | G20: =' gsis'!I17 -> 7340.76
A21: PAG-IBIG | C21: ='PAG-IBIG'!H14 -> 2000 | E21: PAG-IBIG | G21: ='PAG-IBIG'!H15 -> 500
A22: LBP | E22: LBP
A23: DBP | E23: DBP | G23: =DBP!G19 -> 14483.61
A24: CNGWMPC | C24: =CNGWMPC!S15 -> 26407.68 | E24: CNGWMPC | G24: =CNGWMPC!S16 -> 701.11
A25: UOLI | E25: UOLI
A26: GSIS Real State Loan | E26: PAG IBIG Cal. Loan
A27: GSIS Calamity Loan | E27: GSIS MPL | G27: =' gsis'!$R$17 -> 12189.13
A28: Nursery | E28: Nursery
A29: GSIS Em. Loan | E29: GSIS MP Lite | G29: =' gsis'!$S$17 -> 2333.33
A30: GSIS Educ loan | E30: GSIS GFAL | G30: =' gsis'!$Q$17 -> 9634.44
A31: PAG IBIG Loyalty Card | E31: GSIS Educ Loan
A32: TOTAL DEDUCTION | C32: =SUM(C12:C31) -> 69340 | E32: TOTAL DEDUCTION | G32: =SUM(G12:G31) -> 62084
A33: NET PAY | C33: =C9+C10-C32 -> 83940 | E33: NET PAY | G33: =G9+G10-G32 -> 21480
A35: MELINDA R. BARCELONA | E35: =A35 -> MELINDA R. BARCELONA
A36: AO V/PAYROLL CLERK | E36: =A36 -> AO V/PAYROLL CLERK
A39: Republic of the Philippines | E39: Republic of the Philippines
A40: PROVINCE OF CAMARINES NORTE | E40: PROVINCE OF CAMARINES NORTE
A41: D A E T | E41: D A E T
A42: OFFICE OF THE PROVINCIAL AGRICULTURIST | E42: OFFICE OF THE PROVINCIAL AGRICULTURIST
A43: PAY SLIP | E43: PAY SLIP
...

Sheet PHIC (1)
F6: OFFICE OF THE PROVINCIAL AGRICULTURIST
F9: PHILHEALTH CONTRIBUTION REMITTANCE
F10: For the period covered FEBRUARY 2026
E12: NAME | F12: BIRTHDATE | H12: PHILHEALTH NO.
A13: No. | B13: LAST NAME | C13: FIRST NAME | D13: MIDDLE NAME | E13: EXT. | W13: PS | X13: GS
A14: 1 | B14: ABAD | C14: ALMIRANTE | D14: ANDAYA | F14: 25309 | H14: 1 | I14: 9 | K14: 0 | L14: 0 | M14: 0 | N14: 0 | O14: 7 | P14: 8 | Q14: 8 | R14: 7 | S14: 7 | T14: 2 | W14: 2500 | X14: 2500
A15: 2 | B15: BELARDO | C15: RAPHY | D15: BASQUIÑAS | F15: 27998 | H15: 1 | I15: 0 | K15: 0 | L15: 0 | M15: 0 | N15: 0 | O15: 9 | P15: 2 | Q15: 4 | R15: 3 | S15: 2 | T15: 0 | W15: 2039.1 | X15: 2039.1 | AA15: *
A16: 3 | B16: NASOL | C16: MARIA GISELA | D16: CENETA | F16: 26680 | H16: 1 | I16: 0 | K16: 0 | L16: 0 | M16: 0 | N16: 0 | O16: 7 | P16: 4 | Q16: 1 | R16: 7 | S16: 2 | T16: 2 | W16: 1954.05 | X16: 1954.05
A17: 4 | B17: CERENO | C17: MARLENE | D17: VALENCIA | F17: 33118 | H17: 1 | I17: 0 | K17: 2 | L17: 0 | M17: 1 | N17: 8 | O17: 1 | P17: 4 | Q17: 9 | R17: 0 | S17: 7 | T17: 6 | W17: 1035.32 | X17: 1035.33
A18: 5 | B18: BARCELONA | C18: MELINDA | D18: RAMOS | F18: 23889 | H18: 1 | I18: 0 | K18: 0 | L18: 0 | M18: 0 | N18: 0 | O18: 3 | P18: 2 | Q18: 1 | R18: 4 | S18: 8 | T18: 0 | W18: 1282.6 | X18: 1282.6
A19: 6 | B19: OBUSAN | C19: ELNORA | D19: BANAL | F19: 26324 | H19: 1 | I19: 0 | K19: 0 | L19: 0 | M19: 0 | N19: 0 | O19: 3 | P19: 2 | Q19: 1 | R19: 4 | S19: 4 | T19: 8 | W19: 952.95 | X19: 952.95
A20: 7 | B20: DE JESUS | C20: EDWIN | D20: VALERIO | F20: 28404 | H20: 1 | I20: 0 | K20: 0 | L20: 0 | M20: 0 | N20: 0 | O20: 9 | P20: 0 | Q20: 0 | R20: 8 | S20: 5 | T20: 5 | W20: 1025.15 | X20: 1025.15
A21: 8 | B21: MAGANA | C21: GLENDA | D21: MEDRANO | F21: 25553 | H21: 1 | I21: 0 | K21: 2 | L21: 0 | M21: 1 | N21: 2 | O21: 5 | P21: 8 | Q21: 7 | R21: 8 | S21: 5 | T21: 3 | W21: 430.22 | X21: 430.23
A22: 9 | B22: VELACRUZ | C22: PEDRO | D22: SENTIN | E22: III | F22: 26265 | H22: 1 | I22: 0 | K22: 0 | L22: 0 | M22: 0 | N22: 0 | O22: 9 | P22: 8 | Q22: 1 | R22: 8 | S22: 4 | T22: 7 | W22: 453.32 | X22: 453.33
A23: 10 | B23: ARCIGA | C23: SALLY | D23: REYES | F23: 28312 | H23: 1 | I23: 0 | K23: 0 | L23: 2 | M23: 5 | N23: 0 | O23: 4 | P23: 0 | Q23: 1 | R23: 2 | S23: 9 | T23: 3 | W23: 402.2 | X23: 402.2
A24: 11 | B24: QUIBRAL | C24: MACK LENNON | D24: GONZALES | F24: 35129 | H24: 1 | I24: 0 | K24: 0 | L24: 0 | M24: 0 | N24: 1 | O24: 1 | P24: 9 | Q24: 2 | R24: 1 | S24: 3 | T24: 7 | W24: 649.9 | X24: 649.9
A25: 12 | B25: JAUCIAN | C25: GEMMA | D25: SABULARCE | F25: 24970 | H25: 1 | I25: 0 | K25: 0 | L25: 2 | M25: 5 | N25: 0 | O25: 9 | P25: 1 | Q25: 6 | R25: 1 | S25: 9 | T25: 6 | W25: 510.2 | X25: 510.2
A26: 13 | B26: DORIMAN | C26: DULCE | D26: DELFINO | F26: 28367 | H26: 1 | I26: 0 | K26: 0 | L26: 0 | M26: 0 | N26: 0 | O26: 2 | P26: 0 | Q26: 7 | R26: 8 | S26: 2 | T26: 0 | W26: 1309.17 | X26: 1309.18
A27: 14 | B27: MALALUAN | C27: SANTIAGO | D27: GONZALEZ | F27: 22487 | H27: 1 | I27: 0 | K27: 0 | L27: 0 | M27: 0 | N27: 0 | O27: 8 | P27: 2 | Q27: 3 | R27: 8 | S27: 9 | T27: 3 | W27: 1077.25 | X27: 1077.25
A28: 15 | B28: SALVANERA | C28: CELESTE | D28: MAGO | F28: 30185 | H28: 1 | I28: 0 | K28: 0 | L28: 0 | M28: 0 | N28: 0 | O28: 8 | P28: 9 | Q28: 5 | R28: 8 | S28: 9 | T28: 4 | W28: 1282.6 | X28: 1282.6
A29: 16 | B29: CLACIO | C29: ALGEM MARIE | D29: JAUCIAN | F29: 34606 | H29: 1 | I29: 0 | K29: 2 | L29: 5 | M29: 0 | N29: 6 | O29: 4 | P29: 7 | Q29: 2 | R29: 8 | S29: 0 | T29: 3 | W29: 925.6 | X29: 925.6
A30: 17 | B30: PALAD | C30: CHRISTINE | D30: LOLOS | F30: 35890 | H30: 1 | I30: 0 | K30: 2 | L30: 5 | M30: 0 | N30: 7 | O30: 0 | P30: 5 | Q30: 9 | R30: 1 | S30: 5 | T30: 2 | W30: 649.9 | X30: 649.9
A31: 18 | B31: MIRAÑA | C31: CESAR | D31: REMETIR | F31: 22351 | H31: 1 | I31: 0 | K31: 0 | L31: 0 | M31: 0 | N31: 0 | O31: 4 | P31: 4 | Q31: 6 | R31: 2 | S31: 1 | T31: 6 | W31: 1309.17 | X31: 1309.18
A32: 19 | B32: MENESES | C32: BRENDA | D32: RELANO | F32: 29908 | H32: 1 | I32: 3 | K32: 0 | L32: 2 | M32: 5 | N32: 0 | O32: 6 | P32: 8 | Q32: 8 | R32: 9 | S32: 7 | T32: 1 | W32: 1035.32 | X32: 1035.33
A33: 20 | B33: ASIS | C33: RONNIE | D33: RIVERA | F33: 27392 | H33: 1 | I33: 0 | K33: 0 | L33: 0 | M33: 0 | N33: 0 | O33: 2 | P33: 0 | Q33: 8 | R33: 0 | S33: 2 | T33: 1 | W33: 1056.02 | X33: 1056.03
A34: 21 | B34: VILLAFLORES | C34: RYAN | D34: IBANA | F34: 29471 | H34: 1 | I34: 0 | K34: 0 | L34: 0 | M34: 0 | N34: 1 | O34: 0 | P34: 7 | Q34: 7 | R34: 0 | S34: 3 | T34: 6 | W34: 1025.15 | X34: 1025.15
... A37: 24 | B37: CANARIA | C37: JAY | D37: QUINITO | F37: 33010 | H37: 2 | I37: 2 | K37: 0 | L37: 0 | M37: 0 | N37: 0 | O37: 5 | P37: 0 | Q37: 9 | R37: 5 | S37: 3 | T37: 2 | W37: 1025.15 | X37: 1025.15
A38: 25 | B38: JEREZ | C38: MELINDA | D38: LAGATUZ | F38: 22944 | H38: 1 | I38: 0 | J38: 0 | K38: 0 | L38: 0 | M38: 0 | N38: 0 | O38: 2 | P38: 0 | Q38: 8 | R38: 5 | S38: 3 | T38: 6 | W38: 2010.27 | X38: 2010.28
A39: 26 | B39: CARRIDO | C39: RAUL | D39: MORENO | F39: 22990 | H39: 1 | I39: 0 | K39: 0 | L39: 0 | M39: 0 | N39: 0 | O39: 1 | P39: 3 | Q39: 1 | R39: 3 | S39: 4 | T39: 3 | W39: 1025.15 | X39: 1025.15
A40: 27 | B40: RAMOS | C40: ROWENA | D40: VILLAUNA | F40: 23033 | H40: 1 | I40: 0 | K40: 0 | L40: 0 | M40: 0 | N40: 0 | O40: 0 | P40: 4 | Q40: 3 | R40: 3 | S40: 6 | T40: 8 | W40: 1282.6 | X40: 1282.6
A41: 28 | B41: RODRIGUEZ | C41: DESIREE | D41: JABINES | F41: 35258 | H41: 1 | I41: 0 | K41: 2 | L41: 5 | M41: 0 | N41: 7 | O41: 4 | P41: 2 | Q41: 7 | R41: 3 | S41: 0 | T41: 6 | W41: 1005.2 | X41: 1005.2
A42: 29 | B42: BURAC | C42: ISAIAS | D42: REAMBON | F42: 32178 | H42: 0 | I42: 8 | K42: 0 | L42: 8 | M42: 0 | N42: 9 | O42: 5 | P42: 9 | Q42: 4 | R42: 2 | S42: 1 | T42: 3 | W42: 1954.05 | X42: 1954.05
A43: 30 | B43: BALANG | C43: EFREN | D43: DE LUNA | F43: 23386 | H43: 2 | I43: 3 | K43: 0 | L43: 0 | M43: 0 | N43: 4 | O43: 3 | P43: 1 | Q43: 3 | R43: 5 | S43: 8 | T43: 7 | W43: 402.2 | X43: 402.2
A44: 31 | B44: ECHANO | C44: GERRY | D44: YARTE | F44: 27602 | H44: 1 | I44: 0 | K44: 2 | L44: 0 | M44: 1 | N44: 1 | O44: 3 | P44: 7 | Q44: 9 | R44: 0 | S44: 6 | T44: 2 | W44: 402.2 | X44: 402.2
A45: 32 | B45: BAGASBAS | C45: RIZALDO | D45: TOLEDANA | F45: 33486 | H45: 1 | I45: 0 | K45: 2 | L45: 0 | M45: 1 | N45: 7 | O45: 3 | P45: 9 | Q45: 5 | R45: 9 | S45: 6 | T45: 4 | W45: 427.1 | X45: 427.1
A46: 33 | B46: QUIJANO | C46: HELEN | D46: REYES | F46: 24685 | H46: 1 | I46: 0 | K46: 0 | L46: 2 | M46: 5 | N46: 3 | O46: 8 | P46: 5 | Q46: 6 | R46: 9 | S46: 4 | T46: 1 | W46: 396.3 | X46: 396.3
A47: 34 | B47: EMATA | C47: MARY DIANNE | D47: ROCAS | F47: 35227 | H47: 1 | I47: 0 | K47: 2 | L47: 0 | M47: 3 | N47: 1 | O47: 6 | P47: 9 | Q47: 2 | R47: 2 | S47: 5 | T47: 0 | W47: 1005.2 | X47: 1005.2
A48: 35 | B48: BOGATE | C48: JOHNSON | D48: DELA AUSTRIA | F48: 35349 | H48: 1 | I48: 0 | K48: 2 | L48: 5 | M48: 3 | N48: 2 | O48: 3 | P48: 6 | Q48: 6 | R48: 0 | S48: 8 | T48: 6 | W48: 750.6 | X48: 750.6
A49: 36 | B49: DELA CRUZ | C49: ALEXIS | D49: RAFAEL | F49: 33073 | H49: 0 | I49: 2 | K49: 0 | L49: 2 | M49: 6 | N49: 5 | O49: 6 | P49: 4 | Q49: 7 | R49: 0 | S49: 8 | T49: 2 | W49: 1005.2 | X49: 1005.2
Q50: TOTAL | W50: =SUM(W14:W49) -> 37646.71 | X50: =SUM(X14:X49) -> 37646.79
...
